Workbook

Sheet Coil Chart
B2: Pre-Defined Parameters: | G2: Color Key: | H2: Puple Cell: | J2: Informational | M2: Coil Calculator instructions:
C3: Voltage: | E3: 390 | H3: Grey Cell: | J3: User-defined value | M3: Go to | N3: https://www.accelinstruments.com/Magnetic/Magnetic-field-calculator.html
C4: Max Current: | E4: 860 | H4: Blue Cell: | J4: Input from coil calculator | M4: Set inner radius to half your specified coil ID
C5: Coil ID (mm): | E5: 10 | H5: Red Text: | J5: Maximum value exceeded | M5: Set the coil length to specified value
C6: *Snubber Rating (Watts): | E6: 5000 | G6: Green Cell, | H6: Yellow Cell, | I6: or Red Cell | J6: Calculated value | M6: Set wire diameter with and without insulation*
B7: *The pulse-power rating of the device that will dissipate the coil's energy | G7: Positive | H7: Neutral | I7: Negative | M7: Input the number of turns calculated by this sheet
M8: Set current to 1A
B9: Notes: | M9: Set distance from center to 0mm
B10: 1: Power the coil will consume when fully charged by the specified voltage source, it is also how much heat the coil will generate when fully charged. | M10: Set permeability and Compac factor to 1
B11: 2: Energy stored within the coil when it is fully charged. It will need to dissipate this when discharging. | M11: Input resulting resistance, inductance, and field values into their respective blue boxes
B12: 3: Amount of power that a device will dissipate when removing energy from the coil. Many devices can handle dozens of times their rated power for a short period of time. | M12: *Not accounting for enamel thickness only has a marginal impact on accuracy
B13: 4: Strength of field the coil generates per amp of current flowing through it. Some coils generate generate weaker overall fields, but do it more efficiently.
B14: 5: How strong the field will be after it is fully charged by the voltage source specified. | M14: To clear this sheet, highlight the blue and grey columns and press 'del' on your keyboard.
B15: 6: How long the coil will take to build OR collapse %98.1 field strength.
B16: 7: This value indicates the average linear rate that a coil will build/collapse its field. In reality the coil's initial rate will be much higher, and will slow down asymptotically.
B17: 8: This is an arbitrary value that multiplies the field constant by the field rate. It is only intended for comparing coils.
L19: Note 1: | M19: Note 2: | N19: Note 3: | O19: Note 4: | P19: Note 5: | Q19: Note 6: | R19: Note 7: | S19: Note 8:
B20: Wire diameter: | C20: Coil Length: | D20: Coil OD: | E20: Coil Volume: | F20: Layers: | G20: Turns/Layer: | H20: Total Turns: | I20: Resistance: | J20: Inductance: | K20: Max Current: | L20: Max Power: | M20: Energy Stored: | N20: Snub Power: | O20: Field Constant: | P20: Max Field: | Q20: Charge Time: | R20: Field Rate: | S20: Rating:
B21: (Millimeter) | C21: (Millimeter) | D21: (Millimeter) | E21: (Cubic Cent.) | F21: # | G21: # | H21: # | I21: (Ohms) | J21: (Microhenry) | K21: (Amperes) | L21: (Kilowatts) | M21: (Joules) | N21: (Kilowatts) | O21: (Millitesla) | P21: (Tesla) | Q21: (Milliseconds) | R21: (Tesla/Second) | S21: (Arbitrary)
B22: 0.7 | C22: 50 | D22: 50 | E22: =(((3.14159 * (D22/2)^2) * C22) - (3.14159 * (($E$5/2)^2)) * C22)/1000 -> 94.2477 | F22: =((D22-$E$5)/2)/B22 -> 28.571429 | G22: =C22/B22 -> 71.428571 | H22: =F22*G22 -> 2040.8163 | I22: 7.924 | J22: 37432.68 | K22: =$E$3/I22 -> 49.217567 | L22: =(K22*$E$3)/1000 -> 19.194851 | M22: =((J22/1000000)*K22^2)/2 -> 45.33788 | N22: =(M22/(Q22/1000))/1000 -> 2.3993564 | O22: 44.3608 | P22: =(O22*K22)/1000 -> 2.1833306 | Q22: =((J22/1000)/I22)*4 -> 18.895851 | R22: =P22/(Q22/1000) -> 115.54551 | S22: =R22*O22 -> 5125.6911
B23: 0.7 | C23: 50 | D23: 30 | E23: =(((3.14159 * (D23/2)^2) * C23) - (3.14159 * (($E$5/2)^2)) * C23)/1000 -> 31.4159 | F23: =((D23-$E$5)/2)/B23 -> 14.285714 | G23: =C23/B23 -> 71.428571 | H23: =F23*G23 -> 1020.4082 | I23: 2.561 | J23: 4870.454 | K23: =$E$3/I23 -> 152.28426 | L23: =(K23*$E$3)/1000 -> 59.390863 | M23: =((J23/1000000)*K23^2)/2 -> 56.474125 | N23: =(M23/(Q23/1000))/1000 -> 7.4238579 | O23: 23.9815 | P23: =(O23*K23)/1000 -> 3.6520051 | Q23: =((J23/1000)/I23)*4 -> 7.6071128 | R23: =P23/(Q23/1000) -> 480.07768 | S23: =R23*O23 -> 11512.983
B24: 0.7 | C24: 50 | D24: 20 | E24: =(((3.14159 * (D24/2)^2) * C24) - (3.14159 * (($E$5/2)^2)) * C24)/1000 -> 11.780962 | F24: =((D24-$E$5)/2)/B24 -> 7.1428571 | G24: =C24/B24 -> 71.428571 | H24: =F24*G24 -> 510.20408 | I24: 0.931 | J24: 740.44 | K24: =$E$3/I24 -> 418.9044 | L24: =(K24*$E$3)/1000 -> 163.37272 | M24: =((J24/1000000)*K24^2)/2 -> 64.966539 | N24: =(M24/(Q24/1000))/1000 -> 20.42159 | O24: 12.371 | P24: =(O24*K24)/1000 -> 5.1822664 | Q24: =((J24/1000)/I24)*4 -> 3.1812675 | R24: =P24/(Q24/1000) -> 1628.9942 | S24: =R24*O24 -> 20152.288
B25: 0.7 | C25: 30 | D25: 50 | E25: =(((3.14159 * (D25/2)^2) * C25) - (3.14159 * (($E$5/2)^2)) * C25)/1000 -> 56.54862 | F25: =((D25-$E$5)/2)/B25 -> 28.571429 | G25: =C25/B25 -> 42.857143 | H25: =F25*G25 -> 1224.4898 | I25: 4.75 | J25: 17804.975 | K25: =$E$3/I25 -> 82.105263 | L25: =(K25*$E$3)/1000 -> 32.021053 | M25: =((J25/1000000)*K25^2)/2 -> 60.01411 | N25: =(M25/(Q25/1000))/1000 -> 4.0026316 | O25: 37.725 | P25: =(O25*K25)/1000 -> 3.0974211 | Q25: =((J25/1000)/I25)*4 -> 14.993663 | R25: =P25/(Q25/1000) -> 206.58201 | S25: =R25*O25 -> 7793.3063
B26: 0.7 | C26: 30 | D26: 30 | E26: =(((3.14159 * (D26/2)^2) * C26) - (3.14159 * (($E$5/2)^2)) * C26)/1000 -> 18.84954 | F26: =((D26-$E$5)/2)/B26 -> 14.285714 | G26: =C26/B26 -> 42.857143 | H26: =F26*G26 -> 612.2449 | I26: 1.537 | J26: 2492.576 | K26: =$E$3/I26 -> 253.74105 | L26: =(K26*$E$3)/1000 -> 98.959011 | M26: =((J26/1000000)*K26^2)/2 -> 80.241658 | N26: =(M26/(Q26/1000))/1000 -> 12.369876 | O26: 21.8199 | P26: =(O26*K26)/1000 -> 5.5366044 | Q26: =((J26/1000)/I26)*4 -> 6.4868601 | R26: =P26/(Q26/1000) -> 853.51069 | S26: =R26*O26 -> 18623.518
A27: this one first | B27: 0.7 | C27: 30 | D27: 20 | E27: =(((3.14159 * (D27/2)^2) * C27) - (3.14159 * (($E$5/2)^2)) * C27)/1000 -> 7.0685775 | F27: =((D27-$E$5)/2)/B27 -> 7.1428571 | G27: =C27/B27 -> 42.857143 | H27: =F27*G27 -> 306.12245 | I27: 0.559 | J27: 399.111 | K27: =$E$3/I27 -> 697.67442 | L27: =(K27*$E$3)/1000 -> 272.09302 | M27: =((J27/1000000)*K27^2)/2 -> 97.133559 | N27: =(M27/(Q27/1000))/1000 -> 34.011628 | O27: 11.6935 | P27: =(O27*K27)/1000 -> 8.1582558 | Q27: =((J27/1000)/I27)*4 -> 2.8558927 | R27: =P27/(Q27/1000) -> 2856.6395 | S27: =R27*O27 -> 33404.114 | U27: < Option 1
B28: 0.7 | C28: 20 | D28: 50 | E28: =(((3.14159 * (D28/2)^2) * C28) - (3.14159 * (($E$5/2)^2)) * C28)/1000 -> 37.69908 | F28: =((D28-$E$5)/2)/B28 -> 28.571429 | G28: =C28/B28 -> 28.571429 | H28: =F28*G28 -> 816.32653 | I28: 3.167 | J28: 9438.713 | K28: =$E$3/I28 -> 123.14493 | L28: =(K28*$E$3)/1000 -> 48.026524 | M28: =((J28/1000000)*K28^2)/2 -> 71.567504 | N28: =(M28/(Q28/1000))/1000 -> 6.0033154 | O28: 31.0527 | P28: =(O28*K28)/1000 -> 3.8239826 | Q28: =((J28/1000)/I28)*4 -> 11.92133 | R28: =P28/(Q28/1000) -> 320.76812 | S28: =R28*O28 -> 9960.7163
B29: 0.7 | C29: 20 | D29: 30 | E29: =(((3.14159 * (D29/2)^2) * C29) - (3.14159 * (($E$5/2)^2)) * C29)/1000 -> 12.56636 | F29: =((D29-$E$5)/2)/B29 -> 14.285714 | G29: =C29/B29 -> 28.571429 | H29: =F29*G29 -> 408.16327 | I29: 1.024 | J29: 1403.712 | K29: =$E$3/I29 -> 380.85938 | L29: =(K29*$E$3)/1000 -> 148.53516 | M29: =((J29/1000000)*K29^2)/2 -> 101.80692 | N29: =(M29/(Q29/1000))/1000 -> 18.566895 | O29: 19.0385 | P29: =(O29*K29)/1000 -> 7.2509912 | Q29: =((J29/1000)/I29)*4 -> 5.48325 | R29: =P29/(Q29/1000) -> 1322.3893 | S29: =R29*O29 -> 25176.309
B30: 0.7 | C30: 20 | D30: 20 | E30: =(((3.14159 * (D30/2)^2) * C30) - (3.14159 * (($E$5/2)^2)) * C30)/1000 -> 4.712385 | F30: =((D30-$E$5)/2)/B30 -> 7.1428571 | G30: =C30/B30 -> 28.571429 | H30: =F30*G30 -> 204.08163 | I30: 0.372 | J30: 236.081 | K30: =$E$3/I30 -> 1048.3871 | L30: =(K30*$E$3)/1000 -> 408.87097 | M30: =((J30/1000000)*K30^2)/2 -> 129.74014 | N30: =(M30/(Q30/1000))/1000 -> 51.108871 | O30: 10.6635 | P30: =(O30*K30)/1000 -> 11.179476 | Q30: =((J30/1000)/I30)*4 -> 2.5385054 | R30: =P30/(Q30/1000) -> 4403.9599 | S30: =R30*O30 -> 46961.626 | U30: < Option 2
B31: 0.7 | C31: 10 | D31: 50 | E31: =(((3.14159 * (D31/2)^2) * C31) - (3.14159 * (($E$5/2)^2)) * C31)/1000 -> 18.84954 | F31: =((D31-$E$5)/2)/B31 -> 28.571429 | G31: =C31/B31 -> 14.285714 | H31: =F31*G31 -> 408.16327 | I31: 1.583 | J31: 2923.152 | K31: =$E$3/I31 -> 246.36766 | L31: =(K31*$E$3)/1000 -> 96.083386 | M31: =((J31/1000000)*K31^2)/2 -> 88.713311 | N31: =(M31/(Q31/1000))/1000 -> 12.010423 | O31: 19.5153 | P31: =(O31*K31)/1000 -> 4.8079387 | Q31: =((J31/1000)/I31)*4 -> 7.3863601 | R31: =P31/(Q31/1000) -> 650.92125 | S31: =R31*O31 -> 12702.923
B32: 0.7 | C32: 10 | D32: 30 | E32: =(((3.14159 * (D32/2)^2) * C32) - (3.14159 * (($E$5/2)^2)) * C32)/1000 -> 6.28318 | F32: =((D32-$E$5)/2)/B32 -> 14.285714 | G32: =C32/B32 -> 14.285714 | H32: =F32*G32 -> 204.08163 | I32: 0.512 | J32: 478.823 | K32: =$E$3/I32 -> 761.71875 | L32: =(K32*$E$3)/1000 -> 297.07031 | M32: =((J32/1000000)*K32^2)/2 -> 138.91025 | N32: =(M32/(Q32/1000))/1000 -> 37.133789 | O32: 12.9081 | P32: =(O32*K32)/1000 -> 9.8323418 | Q32: =((J32/1000)/I32)*4 -> 3.7408047 | R32: =P32/(Q32/1000) -> 2628.4029 | S32: =R32*O32 -> 33927.687 | U32: < Option 3
B33: 0.7 | C33: 10 | D33: 20 | E33: =(((3.14159 * (D33/2)^2) * C33) - (3.14159 * (($E$5/2)^2)) * C33)/1000 -> 2.3561925 | F33: =((D33-$E$5)/2)/B33 -> 7.1428571 | G33: =C33/B33 -> 14.285714 | H33: =F33*G33 -> 102.04082 | I33: 0.186 | J33: 88.21 | K33: =$E$3/I33 -> 2096.7742 | L33: =(K33*$E$3)/1000 -> 817.74194 | M33: =((J33/1000000)*K33^2)/2 -> 193.90596 | N33: =(M33/(Q33/1000))/1000 -> 102.21774 | O33: 7.8017 | P33: =(O33*K33)/1000 -> 16.358403 | Q33: =((J33/1000)/I33)*4 -> 1.8969892 | R33: =P33/(Q33/1000) -> 8623.3505 | S33: =R33*O33 -> 67276.794
B35: 1.02 | C35: 50 | D35: 50 | E35: =(((3.14159 * (D35/2)^2) * C35) - (3.14159 * (($E$5/2)^2)) * C35)/1000 -> 94.2477 | F35: =((D35-$E$5)/2)/B35 -> 19.607843 | G35: =C35/B35 -> 49.019608 | H35: =F35*G35 -> 961.16878 | I35: 1.799 | J35: 8842.6 | K35: =$E$3/I35 -> 216.7871 | L35: =(K35*$E$3)/1000 -> 84.546971 | M35: =((J35/1000000)*K35^2)/2 -> 207.78628 | N35: =(M35/(Q35/1000))/1000 -> 10.568371 | O35: 20.7781 | P35: =(O35*K35)/1000 -> 4.5044241 | Q35: =((J35/1000)/I35)*4 -> 19.661145 | R35: =P35/(Q35/1000) -> 229.10284 | S35: =R35*O35 -> 4760.3217
B36: 1.02 | C36: 50 | D36: 30 | E36: =(((3.14159 * (D36/2)^2) * C36) - (3.14159 * (($E$5/2)^2)) * C36)/1000 -> 31.4159 | F36: =((D36-$E$5)/2)/B36 -> 9.8039216 | G36: =C36/B36 -> 49.019608 | H36: =F36*G36 -> 480.58439 | I36: 0.59 | J36: 1195.4 | K36: =$E$3/I36 -> 661.01695 | L36: =(K36*$E$3)/1000 -> 257.79661 | M36: =((J36/1000000)*K36^2)/2 -> 261.16107 | N36: =(M36/(Q36/1000))/1000 -> 32.224576 | O36: 11.2589 | P36: =(O36*K36)/1000 -> 7.4423237 | Q36: =((J36/1000)/I36)*4 -> 8.1044068 | R36: =P36/(Q36/1000) -> 918.3058 | S36: =R36*O36 -> 10339.113
B37: 1.02 | C37: 50 | D37: 20 | E37: =(((3.14159 * (D37/2)^2) * C37) - (3.14159 * (($E$5/2)^2)) * C37)/1000 -> 11.780962 | F37: =((D37-$E$5)/2)/B37 -> 4.9019608 | G37: =C37/B37 -> 49.019608 | H37: =F37*G37 -> 240.2922 | I37: 0.217 | J37: 187.1 | K37: =$E$3/I37 -> 1797.235 | L37: =(K37*$E$3)/1000 -> 700.92166 | M37: =((J37/1000000)*K37^2)/2 -> 302.17153 | N37: =(M37/(Q37/1000))/1000 -> 87.615207 | O37: 5.8017 | P37: =(O37*K37)/1000 -> 10.427018 | Q37: =((J37/1000)/I37)*4 -> 3.4488479 | R37: =P37/(Q37/1000) -> 3023.3338 | S37: =R37*O37 -> 17540.476
B38: 1.02 | C38: 30 | D38: 50 | E38: =(((3.14159 * (D38/2)^2) * C38) - (3.14159 * (($E$5/2)^2)) * C38)/1000 -> 56.54862 | F38: =((D38-$E$5)/2)/B38 -> 19.607843 | G38: =C38/B38 -> 29.411765 | H38: =F38*G38 -> 576.70127 | I38: 1.081 | J38: 4215 | K38: =$E$3/I38 -> 360.77706 | L38: =(K38*$E$3)/1000 -> 140.70305 | M38: =((J38/1000000)*K38^2)/2 -> 274.31238 | N38: =(M38/(Q38/1000))/1000 -> 17.587882 | O38: 17.5999 | P38: =(O38*K38)/1000 -> 6.3496401 | Q38: =((J38/1000)/I38)*4 -> 15.59667 | R38: =P38/(Q38/1000) -> 407.11512 | S38: =R38*O38 -> 7165.1855 | U38: < Original plan
B39: 1.02 | C39: 30 | D39: 30 | E39: =(((3.14159 * (D39/2)^2) * C39) - (3.14159 * (($E$5/2)^2)) * C39)/1000 -> 18.84954 | F39: =((D39-$E$5)/2)/B39 -> 9.8039216 | G39: =C39/B39 -> 29.411765 | H39: =F39*G39 -> 288.35063 | I39: 0.353 | J39: 607 | K39: =$E$3/I39 -> 1104.8159 | L39: =(K39*$E$3)/1000 -> 430.87819 | M39: =((J39/1000000)*K39^2)/2 -> 370.45759 | N39: =(M39/(Q39/1000))/1000 -> 53.859773 | O39: 10.1709 | P39: =(O39*K39)/1000 -> 11.236972 | Q39: =((J39/1000)/I39)*4 -> 6.878187 | R39: =P39/(Q39/1000) -> 1633.7113 | S39: =R39*O39 -> 16616.314
B40: 1.02 | C40: 30 | D40: 20 | E40: =(((3.14159 * (D40/2)^2) * C40) - (3.14159 * (($E$5/2)^2)) * C40)/1000 -> 7.0685775 | F40: =((D40-$E$5)/2)/B40 -> 4.9019608 | G40: =C40/B40 -> 29.411765 | H40: =F40*G40 -> 144.17532 | I40: 0.13 | J40: 100.6 | K40: =$E$3/I40 -> 3000 | L40: =(K40*$E$3)/1000 -> 1170 | M40: =((J40/1000000)*K40^2)/2 -> 452.7 | N40: =(M40/(Q40/1000))/1000 -> 146.25 | O40: 5.457 | P40: =(O40*K40)/1000 -> 16.371 | Q40: =((J40/1000)/I40)*4 -> 3.0953846 | R40: =P40/(Q40/1000) -> 5288.8419 | S40: =R40*O40 -> 28861.211
B41: 1.02 | C41: 20 | D41: 50 | E41: =(((3.14159 * (D41/2)^2) * C41) - (3.14159 * (($E$5/2)^2)) * C41)/1000 -> 37.69908 | F41: =((D41-$E$5)/2)/B41 -> 19.607843 | G41: =C41/B41 -> 19.607843 | H41: =F41*G41 -> 384.46751 | I41: 0.719 | J41: 2221.2 | K41: =$E$3/I41 -> 542.42003 | L41: =(K41*$E$3)/1000 -> 211.54381 | M41: =((J41/1000000)*K41^2)/2 -> 326.76016 | N41: =(M41/(Q41/1000))/1000 -> 26.442976 | O41: 14.3946 | P41: =(O41*K41)/1000 -> 7.8079193 | Q41: =((J41/1000)/I41)*4 -> 12.357163 | R41: =P41/(Q41/1000) -> 631.85373 | S41: =R41*O41 -> 9095.2817
B42: 1.02 | C42: 20 | D42: 30 | E42: =(((3.14159 * (D42/2)^2) * C42) - (3.14159 * (($E$5/2)^2)) * C42)/1000 -> 12.56636 | F42: =((D42-$E$5)/2)/B42 -> 9.8039216 | G42: =C42/B42 -> 19.607843 | H42: =F42*G42 -> 192.23376 | I42: 0.235 | J42: 341.2 | K42: =$E$3/I42 -> 1659.5745 | L42: =(K42*$E$3)/1000 -> 647.23404 | M42: =((J42/1000000)*K42^2)/2 -> 469.86437 | N42: =(M42/(Q42/1000))/1000 -> 80.904255 | O42: 8.8179 | P42: =(O42*K42)/1000 -> 14.633962 | Q42: =((J42/1000)/I42)*4 -> 5.8076596 | R42: =P42/(Q42/1000) -> 2519.7692 | S42: =R42*O42 -> 22219.073
B43: 1.02 | C43: 20 | D43: 20 | E43: =(((3.14159 * (D43/2)^2) * C43) - (3.14159 * (($E$5/2)^2)) * C43)/1000 -> 4.712385 | F43: =((D43-$E$5)/2)/B43 -> 4.9019608 | G43: =C43/B43 -> 19.607843 | H43: =F43*G43 -> 96.116878 | I43: 0.087 | J43: 59.3 | K43: =$E$3/I43 -> 4482.7586 | L43: =(K43*$E$3)/1000 -> 1748.2759 | M43: =((J43/1000000)*K43^2)/2 -> 595.82045 | N43: =(M43/(Q43/1000))/1000 -> 218.53448 | O43: 4.9413 | P43: =(O43*K43)/1000 -> 22.150655 | Q43: =((J43/1000)/I43)*4 -> 2.7264368 | R43: =P43/(Q43/1000) -> 8124.3971 | S43: =R43*O43 -> 40145.084
...

Sheet Coil Comparison
B3: Coil Field vs Distance
B5: Coil 1 | C5: Coil 2
A6: Wire diameter: | B6: 0.68mm | C6: 0.68
A7: Turns: | B7: 433 | C7: 649
A8: Dimensions: | B8: 10L X 50W | C8: 30L X 30W
A9: Volume: | B9: 18.85 | C9: 18.85
A10: Current: | B10: 211.2 | C10: 213.8
A11: Time constant: | B11: 1.89 | C11: 1.69
A12: Field: | B12: 4.21 | C12: 4.88
B14: Coil Field vs Time
E15: Time: (ms) | F15: Coil 1 (%) | G15: Coil 1 (Field) | H15: Coil 2 (%) | I15: Coil 2 (Field) | K15: Distance | L15: Coil 1 Field | M15: Coil 1 % | N15: Coil 2 Field | O15: Coil 2 %
B16: Coil 1 | C16: Coil 2 | E16: 0 | F16: 0 | G16: 0 | H16: 0 | I16: 0 | K16: 0 | L16: 4210 | M16: =(L16/$L$16)*100 -> 100 | N16: 4876 | O16: =(N16/$N$16)*100 -> 100
A17: Wire diameter: | B17: 0.68mm | C17: 1.02mm | E17: 1 | F17: 63 | G17: =$B$21*(F17/100) -> 5.3046 | H17: =63*0.63 -> 39.69 | I17: =$C$21*(H17/100) -> 2.952936 | K17: 1 | L17: 4174.5337 | M17: =(L17/$L$16)*100 -> 99.15757 | N17: 4869.8911 | O17: =(N17/$N$16)*100 -> 99.874715
A18: Dimensions: | B18: 10L X 30W | C18: 50L X 30W | E18: 2 | F18: =((100-F17)*0.63)+F17 -> 86.31 | G18: =$B$21*(F18/100) -> 7.267302 | H18: 63 | I18: =$C$21*(H18/100) -> 4.6872 | K18: 2 | L18: 4068.5702 | M18: =(L18/$L$16)*100 -> 96.640622 | N18: 4851.3306 | O18: =(N18/$N$16)*100 -> 99.494065
A19: Current: | B19: 643.6A | C19: 661A | E19: 3 | F19: =((100-F18)*0.63)+F18 -> 94.9347 | G19: =$B$21*(F19/100) -> 7.9935017 | H19: =(H20-H18)*0.63+H18 -> 77.6853 | I19: =$C$21*(H19/100) -> 5.7797863 | K19: 4 | L19: 3668.7086 | M19: =(L19/$L$16)*100 -> 87.142722 | N19: 4774.3182 | O19: =(N19/$N$16)*100 -> 97.914647
A20: Time constant: | B20: 0.97ms | C20: 2.03ms | E20: 4 | F20: =((100-F19)*0.63)+F19 -> 98.125839 | G20: =$B$21*(F20/100) -> 8.2621956 | H20: =(100-H18)*0.63+H18 -> 86.31 | I20: =$C$21*(H20/100) -> 6.421464 | K20: 8 | L20: 2542.6327 | M20: =(L20/$L$16)*100 -> 60.395076 | N20: 4419.3509 | O20: =(N20/$N$16)*100 -> 90.63476
A21: Field: | B21: 8.42 | C21: 7.44 | E21: 5 | F21: =((100-F20)*0.63)+F20 -> 99.30656 | G21: =$B$21*(F21/100) -> 8.3616124 | H21: =(H22-H20)*0.63+H20 -> 91.743561 | I21: =$C$21*(H21/100) -> 6.8257209 | K21: 16 | L21: 1115.2852 | M21: =(L21/$L$16)*100 -> 26.491335 | N21: 2436.5278 | O21: =(N21/$N$16)*100 -> 49.969807
E22: 6 | F22: =((100-F21)*0.63)+F21 -> 99.743427 | G22: =$B$21*(F22/100) -> 8.3983966 | H22: =(100-H20)*0.63+H20 -> 94.9347 | I22: =$C$21*(H22/100) -> 7.0631417 | K22: 32 | L22: 289.9525 | M22: =(L22/$L$16)*100 -> 6.8872328 | N22: 323.6481 | O22: =(N22/$N$16)*100 -> 6.6375738
E23: 7 | F23: =((100-F22)*0.63)+F22 -> 99.905068 | G23: =$B$21*(F23/100) -> 8.4120067 | H23: =(H24-H22)*0.63+H22 -> 96.945118 | I23: =$C$21*(H23/100) -> 7.2127167 | K23: 64 | L23: 48.5225 | M23: =(L23/$L$16)*100 -> 1.1525534 | N23: 35.8414 | O23: =(N23/$N$16)*100 -> 0.73505742
E24: 8 | F24: =((100-F23)*0.63)+F23 -> 99.964875 | G24: =$B$21*(F24/100) -> 8.4170425 | H24: =(100-H22)*0.63+H22 -> 98.125839 | I24: =$C$21*(H24/100) -> 7.3005624
E25: 9 | F25: =((100-F24)*0.63)+F24 -> 99.987004 | H25: =(H26-H24)*0.63+H24 -> 98.869694 | I25: =$C$21*(H25/100) -> 7.3559052
E26: 10 | F26: =((100-F25)*0.63)+F25 -> 99.995191 | H26: =(100-H24)*0.63+H24 -> 99.30656 | I26: =$C$21*(H26/100) -> 7.3884081
E27: 11 | F27: =((100-F26)*0.63)+F26 -> 99.998221 | H27: =(H28-H26)*0.63+H26 -> 99.581787 | I27: =$C$21*(H27/100) -> 7.4088849
E28: 12 | F28: =((100-F27)*0.63)+F27 -> 99.999342 | H28: =(100-H26)*0.63+H26 -> 99.743427 | I28: =$C$21*(H28/100) -> 7.420911
E29: 13 | F29: =((100-F28)*0.63)+F28 -> 99.999756 | H29: =(H30-H28)*0.63+H28 -> 99.845261 | I29: =$C$21*(H29/100) -> 7.4284874
E30: 14 | F30: =((100-F29)*0.63)+F29 -> 99.99991 | H30: =(100-H28)*0.63+H28 -> 99.905068 | I30: =$C$21*(H30/100) -> 7.4329371
E31: 15 | F31: =((100-F30)*0.63)+F30 -> 99.999967 | H31: =(H32-H30)*0.63+H30 -> 99.942747 | I31: =$C$21*(H31/100) -> 7.4357403
E32: 16 | F32: =((100-F31)*0.63)+F31 -> 99.999988 | H32: =(100-H30)*0.63+H30 -> 99.964875
E33: 17 | F33: =((100-F32)*0.63)+F32 -> 99.999995 | H33: =(H34-H32)*0.63+H32 -> 99.978816
E34: 18 | F34: =((100-F33)*0.63)+F33 -> 99.999998 | H34: =(100-H32)*0.63+H32 -> 99.987004
E35: 19 | F35: =((100-F34)*0.63)+F34 -> 99.999999 | H35: =(H36-H34)*0.63+H34 -> 99.992162
E36: 20 | F36: =((100-F35)*0.63)+F35 -> 100 | H36: =(100-H34)*0.63+H34 -> 99.995191

Sheet Sim 2.0 100mm
A1: PARAMETERS | E1: TIME INFO | F1: TIME INFO | H1: CAP INFO | N1: COIL INFO | R1: BULLET INFO | W1: RESULTS
A2: CAPACITOR PROPERTIES | E2: Index: | F2: Time: | G2: Next TC: | H2: Cap Voltage: | I2: Cap Charge: | J2: Cap Energy: | K2: IGBT ON: | L2: Ideal Current: | M2: Current @ NTC: | N2: Current: | O2: Inductance: | P2: Time Constant: | Q2: Field Strength: | R2: Force: | S2: Acceleration: | T2: Speed: | U2: Bullet Position: | V2: Nearest | W2: Final Velocity: | X2: Kinetic Energy: | Y2: Energy Spent: | Z2: Efficiency: | AA2: Sensor Pulse: | AB2: Coil Energy:
A3: Voltage: | B3: Capacitance: | C3: Charge: | D3: Energy: | E3: (Number) | F3: (Millisecond) | G3: (Millisecond) | H3: (Volts) | I3: (Coulombs) | J3: (Percentage) | K3: (True/False) | L3: (Amps) | M3: (Amps) | N3: (Amps) | O3: (Microhenry) | P3: (Millisecond) | Q3: (Percentage) | R3: (Newtons) | S3: (M/S^2) | T3: (Meter/Second) | U3: (Millimeter) | W3: (Meter/Second) | X3: (Joules) | Y3: (Joules) | Z3: (Percentage) | AA3: (Milliseconds) | AB3: (Joules)
A4: 385 | B4: 4600 | C4: =A4*(B4/1000000) -> 1.771 | D4: =C4 * A4 * 0.5 -> 340.9175 | E4: 0 | F4: =E4*$A$16 -> 0 | G4: =F4+P4 -> 0.65465116 | H4: =I4/($B$4/1000000) -> 385 | I4: =(B4/1000000)*$A$4 -> 1.771 | J4: =100 -> 100 | K4: =AND(F4>($A$13-$A$16),F4<($B$13+$A$16)) -> TRUE | L4: =(A4/$A$7)*K4 -> 447.67442 | M4: =(L4*0.63) -> 282.03488 | N4: 0 | O4: =IF(ABS(U4)>80,$B$7, LOOKUP(V4,'Force mapping'!$B$7:$B$167,'Force mapping'!$J$7:$J$167)) -> 563 | P4: =IF((K4*1) = 1, ((O4/1000000)/$A$7)*1000, $C$7) -> 0.65465116 | Q4: =(N4/($A$4/$A$7))*100 -> 0 | R4: =IF(ABS(U4)>80, 0, LOOKUP(V4,'Force mapping'!$B$7:$B$167,'Force mapping'!$I$7:$I$167) * (N4/5) * SIGN(U4)) -> 0 | S4: =(R4/($A$10/1000)) -> 0 | T4: =$B$10 -> 0 | U4: =C10 -> 65 | V4: =(ROUND(ABS(U4)*2,0))/2 -> 65 | W4: =T254 -> 1.8919633 | X4: =0.5 * (A10 / 1000) * W4^2 -> 0.06156783 | Y4: =((100 - J254) / 100) * ((((B4 / 1000000) * A4) * A4) / 2) -> 279.41739 | Z4: =(X5 / Y4) -> 0.0002203347 | AA4: =100/W4 -> 52.855149 | AB4: =((LOOKUP(B13,F4:F254,O4:O254)/1000000) * LOOKUP(B13,F4:F254,N4:N254)^2) / 2 -> 17.968868
A5: COIL PROPERTIES | E5: =E4+1 -> 1 | F5: =E5*$A$16 -> 0.05 | G5: =F5+P5 -> 0.70465116 | H5: =I5/($B$4/1000000) -> 385 | I5: =IF((K4*1)=1,I4-((N4/1000)*$A$16),I4) -> 1.771 | J5: =(((I5*H5)/2)/$D$4)*100 -> 100 | K5: =AND(F5>($A$13-$A$16),F5<($B$13+$A$16)) -> TRUE | L5: =(H4/$A$7)*K5 -> 447.67442 | M5: =M4+(L5-M4)*0.63 -> 386.38779 | N5: =N4+((M4-N4)/((G4-F4)/$A$16)) -> 21.540853 | O5: =IF(ABS(U5)>80,$B$7, LOOKUP(V5,'Force mapping'!$B$7:$B$167,'Force mapping'!$J$7:$J$167)) -> 563 | P5: =IF((K5*1) = 1, ((O5/1000000)/$A$7)*1000, $C$7) -> 0.65465116 | Q5: =(N5/($A$4/$A$7))*100 -> 4.8117229 | R5: =IF(ABS(U5)>80, 0, LOOKUP(V5,'Force mapping'!$B$7:$B$167,'Force mapping'!$I$7:$I$167) * (N5/5) * SIGN(U5)) -> 0.79373734 | S5: =(R5/($A$10/1000)) -> 23.07376 | T5: =T4+(S4/1000)*$A$16 -> 0 | U5: =U4-((T4*$A$16) + (0.5 * (T5-T4))) -> 65 | V5: =(ROUND(ABS(U5)*2,0))/2 -> 65 | W5: =W4 - B10 -> 1.8919633 | X5: =(0.5 * (A10 / 1000) * T204^2) - (0.5 * (A10 / 1000) * B10^2) -> 0.061565346 | Y5: =Y4/D4 -> 0.81960413
A6: Resistance: | B6: Inductance: | C6: Time Constant: | E6: =E5+1 -> 2 | F6: =E6*$A$16 -> 0.1 | G6: =F6+P6 -> 0.75465116 | H6: =I6/($B$4/1000000) -> 384.76586 | I6: =IF((K5*1)=1,I5-((N5/1000)*$A$16),I5) -> 1.769923 | J6: =(((I6*H6)/2)/$D$4)*100 -> 99.878406 | K6: =AND(F6>($A$13-$A$16),F6<($B$13+$A$16)) -> TRUE | L6: =(H5/$A$7)*K6 -> 447.67442 | M6: =M5+(L6-M5)*0.63 -> 424.99837 | N6: =N5+((M5-N5)/((G5-F5)/$A$16)) -> 49.406605 | O6: =IF(ABS(U6)>80,$B$7, LOOKUP(V6,'Force mapping'!$B$7:$B$167,'Force mapping'!$J$7:$J$167)) -> 563 | P6: =IF((K6*1) = 1, ((O6/1000000)/$A$7)*1000, $C$7) -> 0.65465116 | Q6: =(N6/($A$4/$A$7))*100 -> 11.03628 | R6: =IF(ABS(U6)>80, 0, LOOKUP(V6,'Force mapping'!$B$7:$B$167,'Force mapping'!$I$7:$I$167) * (N6/5) * SIGN(U6)) -> 1.8205346 | S6: =(R6/($A$10/1000)) -> 52.922516 | T6: =T5+(S5/1000)*$A$16 -> 0.001153688 | U6: =U5-((T5*$A$16) + (0.5 * (T6-T5))) -> 64.999423 | V6: =(ROUND(ABS(U6)*2,0))/2 -> 65
A7: 0.86 | B7: 536 | C7: 0.623 | E7: =E6+1 -> 3 | F7: =E7*$A$16 -> 0.15 | G7: =F7+P7 -> 0.80465116 | H7: =I7/($B$4/1000000) -> 384.22883 | I7: =IF((K6*1)=1,I6-((N6/1000)*$A$16),I6) -> 1.7674526 | J7: =(((I7*H7)/2)/$D$4)*100 -> 99.599794 | K7: =AND(F7>($A$13-$A$16),F7<($B$13+$A$16)) -> TRUE | L7: =(H6/$A$7)*K7 -> 447.40216 | M7: =M6+(L7-M6)*0.63 -> 439.11276 | N7: =N6+((M6-N6)/((G6-F6)/$A$16)) -> 78.093009 | O7: =IF(ABS(U7)>80,$B$7, LOOKUP(V7,'Force mapping'!$B$7:$B$167,'Force mapping'!$J$7:$J$167)) -> 563 | P7: =IF((K7*1) = 1, ((O7/1000000)/$A$7)*1000, $C$7) -> 0.65465116 | Q7: =(N7/($A$4/$A$7))*100 -> 17.444153 | R7: =IF(ABS(U7)>80, 0, LOOKUP(V7,'Force mapping'!$B$7:$B$167,'Force mapping'!$I$7:$I$167) * (N7/5) * SIGN(U7)) -> 2.8775712 | S7: =(R7/($A$10/1000)) -> 83.650326 | T7: =T6+(S6/1000)*$A$16 -> 0.0037998138 | U7: =U6-((T6*$A$16) + (0.5 * (T7-T6))) -> 64.998042 | V7: =(ROUND(ABS(U7)*2,0))/2 -> 65
A8: PROJECTILE PROPERTIES | E8: =E7+1 -> 4 | F8: =E8*$A$16 -> 0.2 | G8: =F8+P8 -> 0.85465116 | H8: =I8/($B$4/1000000) -> 383.37999 | I8: =IF((K7*1)=1,I7-((N7/1000)*$A$16),I7) -> 1.763548 | J8: =(((I8*H8)/2)/$D$4)*100 -> 99.160209 | K8: =AND(F8>($A$13-$A$16),F8<($B$13+$A$16)) -> TRUE | L8: =(H7/$A$7)*K8 -> 446.77771 | M8: =M7+(L8-M7)*0.63 -> 443.94168 | N8: =N7+((M7-N7)/((G7-F7)/$A$16)) -> 105.66645 | O8: =IF(ABS(U8)>80,$B$7, LOOKUP(V8,'Force mapping'!$B$7:$B$167,'Force mapping'!$J$7:$J$167)) -> 563 | P8: =IF((K8*1) = 1, ((O8/1000000)/$A$7)*1000, $C$7) -> 0.65465116 | Q8: =(N8/($A$4/$A$7))*100 -> 23.603416 | R8: =IF(ABS(U8)>80, 0, LOOKUP(V8,'Force mapping'!$B$7:$B$167,'Force mapping'!$I$7:$I$167) * (N8/5) * SIGN(U8)) -> 3.8935975 | S8: =(R8/($A$10/1000)) -> 113.18597 | T8: =T7+(S7/1000)*$A$16 -> 0.0079823301 | U8: =U7-((T7*$A$16) + (0.5 * (T8-T7))) -> 64.995761 | V8: =(ROUND(ABS(U8)*2,0))/2 -> 65
A9: Mass: | B9: Starting Speed: | C9: Starting Position: | E9: =E8+1 -> 5 | F9: =E9*$A$16 -> 0.25 | G9: =F9+P9 -> 0.90465116 | H9: =I9/($B$4/1000000) -> 382.23145 | I9: =IF((K8*1)=1,I8-((N8/1000)*$A$16),I8) -> 1.7582647 | J9: =(((I9*H9)/2)/$D$4)*100 -> 98.566962 | K9: =AND(F9>($A$13-$A$16),F9<($B$13+$A$16)) -> TRUE | L9: =(H8/$A$7)*K9 -> 445.79069 | M9: =M8+(L9-M8)*0.63 -> 445.10656 | N9: =N8+((M8-N8)/((G8-F8)/$A$16)) -> 131.50275 | O9: =IF(ABS(U9)>80,$B$7, LOOKUP(V9,'Force mapping'!$B$7:$B$167,'Force mapping'!$J$7:$J$167)) -> 563 | P9: =IF((K9*1) = 1, ((O9/1000000)/$A$7)*1000, $C$7) -> 0.65465116 | Q9: =(N9/($A$4/$A$7))*100 -> 29.37464 | R9: =IF(ABS(U9)>80, 0, LOOKUP(V9,'Force mapping'!$B$7:$B$167,'Force mapping'!$I$7:$I$167) * (N9/5) * SIGN(U9)) -> 4.8456133 | S9: =(R9/($A$10/1000)) -> 140.86085 | T9: =T8+(S8/1000)*$A$16 -> 0.013641629 | U9: =U8-((T8*$A$16) + (0.5 * (T9-T8))) -> 64.992532 | V9: =(ROUND(ABS(U9)*2,0))/2 -> 65
A10: 34.4 | B10: 0 | C10: 65 | E10: =E9+1 -> 6 | F10: =E10*$A$16 -> 0.3 | G10: =F10+P10 -> 0.95465116 | H10: =I10/($B$4/1000000) -> 380.80207 | I10: =IF((K9*1)=1,I9-((N9/1000)*$A$16),I9) -> 1.7516895 | J10: =(((I10*H10)/2)/$D$4)*100 -> 97.831146 | K10: =AND(F10>($A$13-$A$16),F10<($B$13+$A$16)) -> TRUE | L10: =(H9/$A$7)*K10 -> 444.45517 | M10: =M9+(L10-M9)*0.63 -> 444.69618 | N10: =N9+((M9-N9)/((G9-F9)/$A$16)) -> 155.45473 | O10: =IF(ABS(U10)>80,$B$7, LOOKUP(V10,'Force mapping'!$B$7:$B$167,'Force mapping'!$J$7:$J$167)) -> 563 | P10: =IF((K10*1) = 1, ((O10/1000000)/$A$7)*1000, $C$7) -> 0.65465116 | Q10: =(N10/($A$4/$A$7))*100 -> 34.724952 | R10: =IF(ABS(U10)>80, 0, LOOKUP(V10,'Force mapping'!$B$7:$B$167,'Force mapping'!$I$7:$I$167) * (N10/5) * SIGN(U10)) -> 5.7281958 | S10: =(R10/($A$10/1000)) -> 166.51732 | T10: =T9+(S9/1000)*$A$16 -> 0.020684671 | U10: =U9-((T9*$A$16) + (0.5 * (T10-T9))) -> 64.988329 | V10: =(ROUND(ABS(U10)*2,0))/2 -> 65
A11: SEMICONDUCTOR PROPERTIES | E11: =E10+1 -> 7 | F11: =E11*$A$16 -> 0.35 | G11: =F11+P11 -> 1.0046512 | H11: =I11/($B$4/1000000) -> 379.11234 | I11: =IF((K10*1)=1,I10-((N10/1000)*$A$16),I10) -> 1.7439168 | J11: =(((I11*H11)/2)/$D$4)*100 -> 96.964864 | K11: =AND(F11>($A$13-$A$16),F11<($B$13+$A$16)) -> TRUE | L11: =(H10/$A$7)*K11 -> 442.7931 | M11: =M10+(L11-M10)*0.63 -> 443.49724 | N11: =N10+((M10-N10)/((G10-F10)/$A$16)) -> 177.54599 | O11: =IF(ABS(U11)>80,$B$7, LOOKUP(V11,'Force mapping'!$B$7:$B$167,'Force mapping'!$J$7:$J$167)) -> 563 | P11: =IF((K11*1) = 1, ((O11/1000000)/$A$7)*1000, $C$7) -> 0.65465116 | Q11: =(N11/($A$4/$A$7))*100 -> 39.659625 | R11: =IF(ABS(U11)>80, 0, LOOKUP(V11,'Force mapping'!$B$7:$B$167,'Force mapping'!$I$7:$I$167) * (N11/5) * SIGN(U11)) -> 6.5422148 | S11: =(R11/($A$10/1000)) -> 190.18066 | T11: =T10+(S10/1000)*$A$16 -> 0.029010537 | U11: =U10-((T10*$A$16) + (0.5 * (T11-T10))) -> 64.983132 | V11: =(ROUND(ABS(U11)*2,0))/2 -> 65
A12: On Time: | B12: Off Time: | C12: Max Current: | E12: =E11+1 -> 8 | F12: =E12*$A$16 -> 0.4 | G12: =F12+P12 -> 1.0546512 | H12: =I12/($B$4/1000000) -> 377.1825 | I12: =IF((K11*1)=1,I11-((N11/1000)*$A$16),I11) -> 1.7350395 | J12: =(((I12*H12)/2)/$D$4)*100 -> 95.980189 | K12: =AND(F12>($A$13-$A$16),F12<($B$13+$A$16)) -> TRUE | L12: =(H11/$A$7)*K12 -> 440.82831 | M12: =M11+(L12-M11)*0.63 -> 441.81581 | N12: =N11+((M11-N11)/((G11-F11)/$A$16)) -> 197.85843 | O12: =IF(ABS(U12)>80,$B$7, LOOKUP(V12,'Force mapping'!$B$7:$B$167,'Force mapping'!$J$7:$J$167)) -> 563 | P12: =IF((K12*1) = 1, ((O12/1000000)/$A$7)*1000, $C$7) -> 0.65465116 | Q12: =(N12/($A$4/$A$7))*100 -> 44.196949 | R12: =IF(ABS(U12)>80, 0, LOOKUP(V12,'Force mapping'!$B$7:$B$167,'Force mapping'!$I$7:$I$167) * (N12/5) * SIGN(U12)) -> 7.2906876 | S12: =(R12/($A$10/1000)) -> 211.93859 | T12: =T11+(S11/1000)*$A$16 -> 0.03851957 | U12: =U11-((T11*$A$16) + (0.5 * (T12-T11))) -> 64.976927 | V12: =(ROUND(ABS(U12)*2,0))/2 -> 65
A13: 0 | B13: 3.5 | E13: =E12+1 -> 9 | F13: =E13*$A$16 -> 0.45 | G13: =F13+P13 -> 1.1046512 | H13: =I13/($B$4/1000000) -> 375.03186 | I13: =IF((K12*1)=1,I12-((N12/1000)*$A$16),I12) -> 1.7251466 | J13: =(((I13*H13)/2)/$D$4)*100 -> 94.888782 | K13: =AND(F13>($A$13-$A$16),F13<($B$13+$A$16)) -> TRUE | L13: =(H12/$A$7)*K13 -> 438.5843 | M13: =M12+(L13-M12)*0.63 -> 439.77996 | N13: =N12+((M12-N12)/((G12-F12)/$A$16)) -> 216.49106 | O13: =IF(ABS(U13)>80,$B$7, LOOKUP(V13,'Force mapping'!$B$7:$B$167,'Force mapping'!$J$7:$J$167)) -> 563 | P13: =IF((K13*1) = 1, ((O13/1000000)/$A$7)*1000, $C$7) -> 0.65465116 | Q13: =(N13/($A$4/$A$7))*100 -> 48.359041 | R13: =IF(ABS(U13)>80, 0, LOOKUP(V13,'Force mapping'!$B$7:$B$167,'Force mapping'!$I$7:$I$167) * (N13/5) * SIGN(U13)) -> 7.9772625 | S13: =(R13/($A$10/1000)) -> 231.89717 | T13: =T12+(S12/1000)*$A$16 -> 0.0491165 | U13: =U12-((T12*$A$16) + (0.5 * (T13-T12))) -> 64.969702 | V13: =(ROUND(ABS(U13)*2,0))/2 -> 65
A14: SIMULATION PROPERTIES | E14: =E13+1 -> 10 | F14: =E14*$A$16 -> 0.5 | G14: =F14+P14 -> 1.1546512 | H14: =I14/($B$4/1000000) -> 372.6787 | I14: =IF((K13*1)=1,I13-((N13/1000)*$A$16),I13) -> 1.714322 | J14: =(((I14*H14)/2)/$D$4)*100 -> 93.701745 | K14: =AND(F14>($A$13-$A$16),F14<($B$13+$A$16)) -> TRUE | L14: =(H13/$A$7)*K14 -> 436.08356 | M14: =M13+(L14-M13)*0.63 -> 437.45123 | N14: =N13+((M13-N13)/((G13-F13)/$A$16)) -> 233.54509 | O14: =IF(ABS(U14)>80,$B$7, LOOKUP(V14,'Force mapping'!$B$7:$B$167,'Force mapping'!$J$7:$J$167)) -> 563 | P14: =IF((K14*1) = 1, ((O14/1000000)/$A$7)*1000, $C$7) -> 0.65465116 | Q14: =(N14/($A$4/$A$7))*100 -> 52.168515 | R14: =IF(ABS(U14)>80, 0, LOOKUP(V14,'Force mapping'!$B$7:$B$167,'Force mapping'!$I$7:$I$167) * (N14/5) * SIGN(U14)) -> 8.6056696 | S14: =(R14/($A$10/1000)) -> 250.16481 | T14: =T13+(S13/1000)*$A$16 -> 0.060711358 | U14: =U13-((T13*$A$16) + (0.5 * (T14-T13))) -> 64.961449 | V14: =(ROUND(ABS(U14)*2,0))/2 -> 65
A15: Time Increment: | E15: =E14+1 -> 11 | F15: =E15*$A$16 -> 0.55 | G15: =F15+P15 -> 1.2046512 | H15: =I15/($B$4/1000000) -> 370.14016 | I15: =IF((K14*1)=1,I14-((N14/1000)*$A$16),I14) -> 1.7026448 | J15: =(((I15*H15)/2)/$D$4)*100 -> 92.429577 | K15: =AND(F15>($A$13-$A$16),F15<($B$13+$A$16)) -> TRUE | L15: =(H14/$A$7)*K15 -> 433.34732 | M15: =M14+(L15-M14)*0.63 -> 434.86577 | N15: =N14+((M14-N14)/((G14-F14)/$A$16)) -> 249.11874 | O15: =IF(ABS(U15)>80,$B$7, LOOKUP(V15,'Force mapping'!$B$7:$B$167,'Force mapping'!$J$7:$J$167)) -> 563 | P15: =IF((K15*1) = 1, ((O15/1000000)/$A$7)*1000, $C$7) -> 0.65465116 | Q15: =(N15/($A$4/$A$7))*100 -> 55.647303 | R15: =IF(ABS(U15)>80, 0, LOOKUP(V15,'Force mapping'!$B$7:$B$167,'Force mapping'!$I$7:$I$167) * (N15/5) * SIGN(U15)) -> 9.1795274 | S15: =(R15/($A$10/1000)) -> 266.84673 | T15: =T14+(S14/1000)*$A$16 -> 0.073219599 | U15: =U14-((T14*$A$16) + (0.5 * (T15-T14))) -> 64.952159 | V15: =(ROUND(ABS(U15)*2,0))/2 -> 65
A16: 0.05 | E16: =E15+1 -> 12 | F16: =E16*$A$16 -> 0.6 | G16: =F16+P16 -> 1.2546512 | H16: =I16/($B$4/1000000) -> 367.43235 | I16: =IF((K15*1)=1,I15-((N15/1000)*$A$16),I15) -> 1.6901888 | J16: =(((I16*H16)/2)/$D$4)*100 -> 91.082161 | K16: =AND(F16>($A$13-$A$16),F16<($B$13+$A$16)) -> TRUE | L16: =(H15/$A$7)*K16 -> 430.39554 | M16: =M15+(L16-M15)*0.63 -> 432.04952 | N16: =N15+((M15-N15)/((G15-F15)/$A$16)) -> 263.30546 | O16: =IF(ABS(U16)>80,$B$7, LOOKUP(V16,'Force mapping'!$B$7:$B$167,'Force mapping'!$J$7:$J$167)) -> 563 | P16: =IF((K16*1) = 1, ((O16/1000000)/$A$7)*1000, $C$7) -> 0.65465116 | Q16: =(N16/($A$4/$A$7))*100 -> 58.816285 | R16: =IF(ABS(U16)>80, 0, LOOKUP(V16,'Force mapping'!$B$7:$B$167,'Force mapping'!$I$7:$I$167) * (N16/5) * SIGN(U16)) -> 9.7022796 | S16: =(R16/($A$10/1000)) -> 282.04301 | T16: =T15+(S15/1000)*$A$16 -> 0.086561935 | U16: =U15-((T15*$A$16) + (0.5 * (T16-T15))) -> 64.941827 | V16: =(ROUND(ABS(U16)*2,0))/2 -> 65
E17: =E16+1 -> 13 | F17: =E17*$A$16 -> 0.65 | G17: =F17+P17 -> 1.3046512 | H17: =I17/($B$4/1000000) -> 364.57034 | I17: =IF((K16*1)=1,I16-((N16/1000)*$A$16),I16) -> 1.6770235 | J17: =(((I17*H17)/2)/$D$4)*100 -> 89.668767 | K17: =AND(F17>($A$13-$A$16),F17<($B$13+$A$16)) -> TRUE | L17: =(H16/$A$7)*K17 -> 427.24692 | M17: =M16+(L17-M16)*0.63 -> 429.02388 | N17: =N16+((M16-N16)/((G16-F16)/$A$16)) -> 276.19355 | O17: =IF(ABS(U17)>80,$B$7, LOOKUP(V17,'Force mapping'!$B$7:$B$167,'Force mapping'!$J$7:$J$167)) -> 563 | P17: =IF((K17*1) = 1, ((O17/1000000)/$A$7)*1000, $C$7) -> 0.65465116 | Q17: =(N17/($A$4/$A$7))*100 -> 61.695183 | R17: =IF(ABS(U17)>80, 0, LOOKUP(V17,'Force mapping'!$B$7:$B$167,'Force mapping'!$I$7:$I$167) * (N17/5) * SIGN(U17)) -> 10.17718 | S17: =(R17/($A$10/1000)) -> 295.84825 | T17: =T16+(S16/1000)*$A$16 -> 0.10066409 | U17: =U16-((T16*$A$16) + (0.5 * (T17-T16))) -> 64.930448 | V17: =(ROUND(ABS(U17)*2,0))/2 -> 65
E18: =E17+1 -> 14 | F18: =E18*$A$16 -> 0.7 | G18: =F18+P18 -> 1.3546512 | H18: =I18/($B$4/1000000) -> 361.56823 | I18: =IF((K17*1)=1,I17-((N17/1000)*$A$16),I17) -> 1.6632139 | J18: =(((I18*H18)/2)/$D$4)*100 -> 88.198068 | K18: =AND(F18>($A$13-$A$16),F18<($B$13+$A$16)) -> TRUE | L18: =(H17/$A$7)*K18 -> 423.91899 | M18: =M17+(L18-M17)*0.63 -> 425.8078 | N18: =N17+((M17-N17)/((G17-F17)/$A$16)) -> 287.8662 | O18: =IF(ABS(U18)>80,$B$7, LOOKUP(V18,'Force mapping'!$B$7:$B$167,'Force mapping'!$J$7:$J$167)) -> 563 | P18: =IF((K18*1) = 1, ((O18/1000000)/$A$7)*1000, $C$7) -> 0.65465116 | Q18: =(N18/($A$4/$A$7))*100 -> 64.302581 | R18: =IF(ABS(U18)>80, 0, LOOKUP(V18,'Force mapping'!$B$7:$B$167,'Force mapping'!$I$7:$I$167) * (N18/5) * SIGN(U18)) -> 10.607294 | S18: =(R18/($A$10/1000)) -> 308.35157 | T18: =T17+(S17/1000)*$A$16 -> 0.1154565 | U18: =U17-((T17*$A$16) + (0.5 * (T18-T17))) -> 64.918018 | V18: =(ROUND(ABS(U18)*2,0))/2 -> 65
E19: =E18+1 -> 15 | F19: =E19*$A$16 -> 0.75 | G19: =F19+P19 -> 1.4046512 | H19: =I19/($B$4/1000000) -> 358.43925 | I19: =IF((K18*1)=1,I18-((N18/1000)*$A$16),I18) -> 1.6488206 | J19: =(((I19*H19)/2)/$D$4)*100 -> 86.678156 | K19: =AND(F19>($A$13-$A$16),F19<($B$13+$A$16)) -> TRUE | L19: =(H18/$A$7)*K19 -> 420.42818 | M19: =M18+(L19-M18)*0.63 -> 422.41864 | N19: =N18+((M18-N18)/((G18-F18)/$A$16)) -> 298.40171 | O19: =IF(ABS(U19)>80,$B$7, LOOKUP(V19,'Force mapping'!$B$7:$B$167,'Force mapping'!$J$7:$J$167)) -> 563 | P19: =IF((K19*1) = 1, ((O19/1000000)/$A$7)*1000, $C$7) -> 0.65465116 | Q19: =(N19/($A$4/$A$7))*100 -> 66.655966 | R19: =IF(ABS(U19)>80, 0, LOOKUP(V19,'Force mapping'!$B$7:$B$167,'Force mapping'!$I$7:$I$167) * (N19/5) * SIGN(U19)) -> 10.995506 | S19: =(R19/($A$10/1000)) -> 319.63681 | T19: =T18+(S18/1000)*$A$16 -> 0.13087408 | U19: =U18-((T18*$A$16) + (0.5 * (T19-T18))) -> 64.904537 | V19: =(ROUND(ABS(U19)*2,0))/2 -> 65
E20: =E19+1 -> 16 | F20: =E20*$A$16 -> 0.8 | G20: =F20+P20 -> 1.4546512 | H20: =I20/($B$4/1000000) -> 355.19575 | I20: =IF((K19*1)=1,I19-((N19/1000)*$A$16),I19) -> 1.6339005 | J20: =(((I20*H20)/2)/$D$4)*100 -> 85.116562 | K20: =AND(F20>($A$13-$A$16),F20<($B$13+$A$16)) -> TRUE | L20: =(H19/$A$7)*K20 -> 416.78983 | M20: =M19+(L20-M19)*0.63 -> 418.87249 | N20: =N19+((M19-N19)/((G19-F19)/$A$16)) -> 307.87369 | O20: =IF(ABS(U20)>80,$B$7, LOOKUP(V20,'Force mapping'!$B$7:$B$167,'Force mapping'!$J$7:$J$167)) -> 563 | P20: =IF((K20*1) = 1, ((O20/1000000)/$A$7)*1000, $C$7) -> 0.65465116 | Q20: =(N20/($A$4/$A$7))*100 -> 68.771786 | R20: =IF(ABS(U20)>80, 0, LOOKUP(V20,'Force mapping'!$B$7:$B$167,'Force mapping'!$I$7:$I$167) * (N20/5) * SIGN(U20)) -> 11.34453 | S20: =(R20/($A$10/1000)) -> 329.78285 | T20: =T19+(S19/1000)*$A$16 -> 0.14685592 | U20: =U19-((T19*$A$16) + (0.5 * (T20-T19))) -> 64.890002 | V20: =(ROUND(ABS(U20)*2,0))/2 -> 65
E21: =E20+1 -> 17 | F21: =E21*$A$16 -> 0.85 | G21: =F21+P21 -> 1.5046512 | H21: =I21/($B$4/1000000) -> 351.8493 | I21: =IF((K20*1)=1,I20-((N20/1000)*$A$16),I20) -> 1.6185068 | J21: =(((I21*H21)/2)/$D$4)*100 -> 83.520277 | K21: =AND(F21>($A$13-$A$16),F21<($B$13+$A$16)) -> TRUE | L21: =(H20/$A$7)*K21 -> 413.01832 | M21: =M20+(L21-M20)*0.63 -> 415.18436 | N21: =N20+((M20-N20)/((G20-F20)/$A$16)) -> 316.3514 | O21: =IF(ABS(U21)>80,$B$7, LOOKUP(V21,'Force mapping'!$B$7:$B$167,'Force mapping'!$J$7:$J$167)) -> 563 | P21: =IF((K21*1) = 1, ((O21/1000000)/$A$7)*1000, $C$7) -> 0.65465116 | Q21: =(N21/($A$4/$A$7))*100 -> 70.665507 | R21: =IF(ABS(U21)>80, 0, LOOKUP(V21,'Force mapping'!$B$7:$B$167,'Force mapping'!$I$7:$I$167) * (N21/5) * SIGN(U21)) -> 11.656916 | S21: =(R21/($A$10/1000)) -> 338.86385 | T21: =T20+(S20/1000)*$A$16 -> 0.16334506 | U21: =U20-((T20*$A$16) + (0.5 * (T21-T20))) -> 64.874415 | V21: =(ROUND(ABS(U21)*2,0))/2 -> 65
E22: =E21+1 -> 18 | F22: =E22*$A$16 -> 0.9 | G22: =F22+P22 -> 1.5546512 | H22: =I22/($B$4/1000000) -> 348.4107 | I22: =IF((K21*1)=1,I21-((N21/1000)*$A$16),I21) -> 1.6026892 | J22: =(((I22*H22)/2)/$D$4)*100 -> 81.895777 | K22: =AND(F22>($A$13-$A$16),F22<($B$13+$A$16)) -> TRUE | L22: =(H21/$A$7)*K22 -> 409.12709 | M22: =M21+(L22-M21)*0.63 -> 411.36828 | N22: =N21+((M21-N21)/((G21-F21)/$A$16)) -> 323.89992 | O22: =IF(ABS(U22)>80,$B$7, LOOKUP(V22,'Force mapping'!$B$7:$B$167,'Force mapping'!$J$7:$J$167)) -> 563 | P22: =IF((K22*1) = 1, ((O22/1000000)/$A$7)*1000, $C$7) -> 0.65465116 | Q22: =(N22/($A$4/$A$7))*100 -> 72.35167 | R22: =IF(ABS(U22)>80, 0, LOOKUP(V22,'Force mapping'!$B$7:$B$167,'Force mapping'!$I$7:$I$167) * (N22/5) * SIGN(U22)) -> 11.935064 | S22: =(R22/($A$10/1000)) -> 346.94954 | T22: =T21+(S21/1000)*$A$16 -> 0.18028825 | U22: =U21-((T21*$A$16) + (0.5 * (T22-T21))) -> 64.857776 | V22: =(ROUND(ABS(U22)*2,0))/2 -> 65
E23: =E22+1 -> 19 | F23: =E23*$A$16 -> 0.95 | G23: =F23+P23 -> 1.6046512 | H23: =I23/($B$4/1000000) -> 344.89005 | I23: =IF((K22*1)=1,I22-((N22/1000)*$A$16),I22) -> 1.5864942 | J23: =(((I23*H23)/2)/$D$4)*100 -> 80.249043 | K23: =AND(F23>($A$13-$A$16),F23<($B$13+$A$16)) -> TRUE | L23: =(H22/$A$7)*K23 -> 405.12872 | M23: =M22+(L23-M22)*0.63 -> 407.43736 | N23: =N22+((M22-N22)/((G22-F22)/$A$16)) -> 330.58045 | O23: =IF(ABS(U23)>80,$B$7, LOOKUP(V23,'Force mapping'!$B$7:$B$167,'Force mapping'!$J$7:$J$167)) -> 563 | P23: =IF((K23*1) = 1, ((O23/1000000)/$A$7)*1000, $C$7) -> 0.65465116 | Q23: =(N23/($A$4/$A$7))*100 -> 73.843945 | R23: =IF(ABS(U23)>80, 0, LOOKUP(V23,'Force mapping'!$B$7:$B$167,'Force mapping'!$I$7:$I$167) * (N23/5) * SIGN(U23)) -> 12.181229 | S23: =(R23/($A$10/1000)) -> 354.10548 | T23: =T22+(S22/1000)*$A$16 -> 0.19763573 | U23: =U22-((T22*$A$16) + (0.5 * (T23-T22))) -> 64.840088 | V23: =(ROUND(ABS(U23)*2,0))/2 -> 65
E24: =E23+1 -> 20 | F24: =E24*$A$16 -> 1 | G24: =F24+P24 -> 1.6546512 | H24: =I24/($B$4/1000000) -> 341.29678 | I24: =IF((K23*1)=1,I23-((N23/1000)*$A$16),I23) -> 1.5699652 | J24: =(((I24*H24)/2)/$D$4)*100 -> 78.585592 | K24: =AND(F24>($A$13-$A$16),F24<($B$13+$A$16)) -> TRUE | L24: =(H23/$A$7)*K24 -> 401.03494 | M24: =M23+(L24-M23)*0.63 -> 403.40383 | N24: =N23+((M23-N23)/((G23-F23)/$A$16)) -> 336.45052 | O24: =IF(ABS(U24)>80,$B$7, LOOKUP(V24,'Force mapping'!$B$7:$B$167,'Force mapping'!$J$7:$J$167)) -> 563 | P24: =IF((K24*1) = 1, ((O24/1000000)/$A$7)*1000, $C$7) -> 0.65465116 | Q24: =(N24/($A$4/$A$7))*100 -> 75.155181 | R24: =IF(ABS(U24)>80, 0, LOOKUP(V24,'Force mapping'!$B$7:$B$167,'Force mapping'!$I$7:$I$167) * (N24/5) * SIGN(U24)) -> 12.397529 | S24: =(R24/($A$10/1000)) -> 360.39328 | T24: =T23+(S23/1000)*$A$16 -> 0.215341 | U24: =U23-((T23*$A$16) + (0.5 * (T24-T23))) -> 64.821353 | V24: =(ROUND(ABS(U24)*2,0))/2 -> 65
E25: =E24+1 -> 21 | F25: =E25*$A$16 -> 1.05 | G25: =F25+P25 -> 1.7046512 | H25: =I25/($B$4/1000000) -> 337.63971 | I25: =IF((K24*1)=1,I24-((N24/1000)*$A$16),I24) -> 1.5531427 | J25: =(((I25*H25)/2)/$D$4)*100 -> 76.91049 | K25: =AND(F25>($A$13-$A$16),F25<($B$13+$A$16)) -> TRUE | L25: =(H24/$A$7)*K25 -> 396.85672 | M25: =M24+(L25-M24)*0.63 -> 399.27915 | N25: =N24+((M24-N24)/((G24-F24)/$A$16)) -> 341.56418 | O25: =IF(ABS(U25)>80,$B$7, LOOKUP(V25,'Force mapping'!$B$7:$B$167,'Force mapping'!$J$7:$J$167)) -> 563 | P25: =IF((K25*1) = 1, ((O25/1000000)/$A$7)*1000, $C$7) -> 0.65465116 | Q25: =(N25/($A$4/$A$7))*100 -> 76.297454 | R25: =IF(ABS(U25)>80, 0, LOOKUP(V25,'Force mapping'!$B$7:$B$167,'Force mapping'!$I$7:$I$167) * (N25/5) * SIGN(U25)) -> 12.585957 | S25: =(R25/($A$10/1000)) -> 365.87084 | T25: =T24+(S24/1000)*$A$16 -> 0.23336067 | U25: =U24-((T24*$A$16) + (0.5 * (T25-T24))) -> 64.801577 | V25: =(ROUND(ABS(U25)*2,0))/2 -> 65
E26: =E25+1 -> 22 | F26: =E26*$A$16 -> 1.1 | G26: =F26+P26 -> 1.7546512 | H26: =I26/($B$4/1000000) -> 333.92706 | I26: =IF((K25*1)=1,I25-((N25/1000)*$A$16),I25) -> 1.5360645 | J26: =(((I26*H26)/2)/$D$4)*100 -> 75.228389 | K26: =AND(F26>($A$13-$A$16),F26<($B$13+$A$16)) -> TRUE | L26: =(H25/$A$7)*K26 -> 392.60431 | M26: =M25+(L26-M25)*0.63 -> 395.07401 | N26: =N25+((M25-N25)/((G25-F25)/$A$16)) -> 345.97225 | O26: =IF(ABS(U26)>80,$B$7, LOOKUP(V26,'Force mapping'!$B$7:$B$167,'Force mapping'!$J$7:$J$167)) -> 563 | P26: =IF((K26*1) = 1, ((O26/1000000)/$A$7)*1000, $C$7) -> 0.65465116 | Q26: =(N26/($A$4/$A$7))*100 -> 77.282113 | R26: =IF(ABS(U26)>80, 0, LOOKUP(V26,'Force mapping'!$B$7:$B$167,'Force mapping'!$I$7:$I$167) * (N26/5) * SIGN(U26)) -> 12.748386 | S26: =(R26/($A$10/1000)) -> 370.5926 | T26: =T25+(S25/1000)*$A$16 -> 0.25165421 | U26: =U25-((T25*$A$16) + (0.5 * (T26-T25))) -> 64.780762 | V26: =(ROUND(ABS(U26)*2,0))/2 -> 65
E27: =E26+1 -> 23 | F27: =E27*$A$16 -> 1.15 | G27: =F27+P27 -> 1.8046512 | H27: =I27/($B$4/1000000) -> 330.16649 | I27: =IF((K26*1)=1,I26-((N26/1000)*$A$16),I26) -> 1.5187658 | J27: =(((I27*H27)/2)/$D$4)*100 -> 73.543539 | K27: =AND(F27>($A$13-$A$16),F27<($B$13+$A$16)) -> TRUE | L27: =(H26/$A$7)*K27 -> 388.28727 | M27: =M26+(L27-M26)*0.63 -> 390.79837 | N27: =N26+((M26-N26)/((G26-F26)/$A$16)) -> 349.72247 | O27: =IF(ABS(U27)>80,$B$7, LOOKUP(V27,'Force mapping'!$B$7:$B$167,'Force mapping'!$J$7:$J$167)) -> 563 | P27: =IF((K27*1) = 1, ((O27/1000000)/$A$7)*1000, $C$7) -> 0.65465116 | Q27: =(N27/($A$4/$A$7))*100 -> 78.119826 | R27: =IF(ABS(U27)>80, 0, LOOKUP(V27,'Force mapping'!$B$7:$B$167,'Force mapping'!$I$7:$I$167) * (N27/5) * SIGN(U27)) -> 12.886574 | S27: =(R27/($A$10/1000)) -> 374.6097 | T27: =T26+(S26/1000)*$A$16 -> 0.27018384 | U27: =U26-((T26*$A$16) + (0.5 * (T27-T26))) -> 64.758914 | V27: =(ROUND(ABS(U27)*2,0))/2 -> 65
E28: =E27+1 -> 24 | F28: =E28*$A$16 -> 1.2 | G28: =F28+P28 -> 1.8604651 | H28: =I28/($B$4/1000000) -> 326.36516 | I28: =IF((K27*1)=1,I27-((N27/1000)*$A$16),I27) -> 1.5012797 | J28: =(((I28*H28)/2)/$D$4)*100 -> 71.859818 | K28: =AND(F28>($A$13-$A$16),F28<($B$13+$A$16)) -> TRUE | L28: =(H27/$A$7)*K28 -> 383.91452 | M28: =M27+(L28-M27)*0.63 -> 386.46154 | N28: =N27+((M27-N27)/((G27-F27)/$A$16)) -> 352.85971 | O28: =IF(ABS(U28)>80,$B$7, LOOKUP(V28,'Force mapping'!$B$7:$B$167,'Force mapping'!$J$7:$J$167)) -> 568 | P28: =IF((K28*1) = 1, ((O28/1000000)/$A$7)*1000, $C$7) -> 0.66046512 | Q28: =(N28/($A$4/$A$7))*100 -> 78.820611 | R28: =IF(ABS(U28)>80, 0, LOOKUP(V28,'Force mapping'!$B$7:$B$167,'Force mapping'!$I$7:$I$167) * (N28/5) * SIGN(U28)) -> 15.249891 | S28: =(R28/($A$10/1000)) -> 443.31078 | T28: =T27+(S27/1000)*$A$16 -> 0.28891432 | U28: =U27-((T27*$A$16) + (0.5 * (T28-T27))) -> 64.73604 | V28: =(ROUND(ABS(U28)*2,0))/2 -> 64.5
... E254: =E253+1 -> 250 | F254: =E254*$A$16 -> 12.5 | G254: =F254+P254 -> 13.123 | H254: =I254/($B$4/1000000) -> 163.52119 | I254: =IF((K253*1)=1,I253-((N253/1000)*$A$16),I253) -> 0.75219746 | J254: =(((I254*H254)/2)/$D$4)*100 -> 18.039587 | K254: =AND(F254>($A$13-$A$16),F254<($B$13+$A$16)) -> FALSE | L254: =(H253/$A$7)*K254 -> 0 | M254: =M253+(L254-M253)*0.63 -> 3.7466126e-76 | N254: =N253+((M253-N253)/((G253-F253)/$A$16)) -> 7.9460866e-05 | O254: =IF(ABS(U254)>80,$B$7, LOOKUP(V254,'Force mapping'!$B$7:$B$167,'Force mapping'!$J$7:$J$167)) -> 1406 | P254: =IF((K254*1) = 1, ((O254/1000000)/$A$7)*1000, $C$7) -> 0.623 | Q254: =(N254/($A$4/$A$7))*100 -> 1.77497e-05 | R254: =IF(ABS(U254)>80, 0, LOOKUP(V254,'Force mapping'!$B$7:$B$167,'Force mapping'!$I$7:$I$167) * (N254/5) * SIGN(U254)) -> 3.9901433e-05 | S254: =(R254/($A$10/1000)) -> 0.0011599254 | T254: =T253+(S253/1000)*$A$16 -> 1.8919633 | U254: =U253-((T253*$A$16) + (0.5 * (T254-T253))) -> 45.388511 | V254: =(ROUND(ABS(U254)*2,0))/2 -> 45.5

Sheet Sim 2.0 50mm
A1: PARAMETERS | E1: TIME INFO | H1: CAP INFO | N1: COIL INFO | R1: BULLET INFO | W1: RESULTS
A2: CAPACITOR PROPERTIES | E2: Index: | F2: Time: | G2: Next TC: | H2: Cap Voltage: | I2: Cap Charge: | J2: Cap Energy: | K2: IGBT ON: | L2: Ideal Current: | M2: Current @ NTC: | N2: Current: | O2: Inductance: | P2: Time Constant: | Q2: Field Strength: | R2: Force: | S2: Acceleration: | T2: Speed: | U2: Bullet Position: | V2: Nearest | W2: Final Velocity: | X2: Kinetic Energy: | Y2: Energy Spent: | Z2: Efficiency: | AA2: Sensor Pulse: | AB2: Coil Energy:
A3: Voltage: | B3: Capacitance: | C3: Charge: | D3: Energy: | E3: (Number) | F3: (Millisecond) | G3: (Millisecond) | H3: (Volts) | I3: (Coulombs) | J3: (Percentage) | K3: (True/False) | L3: (Amps) | M3: (Amps) | N3: (Amps) | O3: (Microhenry) | P3: (Millisecond) | Q3: (Percentage) | R3: (Newtons) | S3: (M/S^2) | T3: (Meter/Second) | U3: (Millimeter) | W3: (Meter/Second) | X3: (Joules) | Y3: (Joules) | Z3: (Percentage) | AA3: (Milliseconds) | AB3: (Joules)
A4: 390 | B4: 4590 | C4: =A4*(B4/1000000) -> 1.7901 | D4: =C4 * A4 * 0.5 -> 349.0695 | E4: 0 | F4: =E4*$A$16 -> 0 | G4: =F4+P4 -> 0.62325581 | H4: =I4/($B$4/1000000) -> 390 | I4: =(B4/1000000)*$A$4 -> 1.7901 | J4: =100 -> 100 | K4: =AND(F4>($A$13-$A$16),F4<($B$13+$A$16)) -> TRUE | L4: =(A4/$A$7)*K4 -> 453.48837 | M4: =(L4*0.63) -> 285.69767 | N4: 0 | O4: =IF(ABS(U4)>80,$B$7, LOOKUP(V4,'Force mapping'!$B$7:$B$167,'Force mapping'!$E$7:$E$167)) -> 536 | P4: =IF((K4*1) = 1, ((O4/1000000)/$A$7)*1000, $C$7) -> 0.62325581 | Q4: =(N4/($A$4/$A$7))*100 -> 0 | R4: =IF(ABS(U4)>80, 0, LOOKUP(V4,'Force mapping'!$B$7:$B$167,'Force mapping'!$D$7:$D$167) * (N4/5) * SIGN(U4)) -> 0 | S4: =(R4/($A$10/1000)) -> 0 | T4: =$B$10 -> 27.98 | U4: =C10 -> 81 | V4: =(ROUND(ABS(U4)*2,0))/2 -> 81 | W4: =T254 -> 32.399884 | X4: =0.5 * (A10 / 1000) * W4^2 -> 9.0278713 | Y4: =((100 - J254) / 100) * ((((B4 / 1000000) * A4) * A4) / 2) -> 210.01973 | Z4: =(X5 / Y4) -> 0.01092802 | AA4: =50/W4 -> 1.5432154 | AB4: =((LOOKUP(B13,F4:F254,O4:O254)/1000000) * LOOKUP(B13,F4:F254,N4:N254)^2) / 2 -> 99.579156
A5: COIL PROPERTIES | E5: =E4+1 -> 1 | F5: =E5*$A$16 -> 0.05 | G5: =F5+P5 -> 0.67325581 | H5: =I5/($B$4/1000000) -> 390 | I5: =IF((K4*1)=1,I4-((N4/1000)*$A$16),I4) -> 1.7901 | J5: =(((I5*H5)/2)/$D$4)*100 -> 100 | K5: =AND(F5>($A$13-$A$16),F5<($B$13+$A$16)) -> TRUE | L5: =(H4/$A$7)*K5 -> 453.48837 | M5: =M4+(L5-M4)*0.63 -> 391.40581 | N5: =N4+((M4-N4)/((G4-F4)/$A$16)) -> 22.919776 | O5: =IF(ABS(U5)>80,$B$7, LOOKUP(V5,'Force mapping'!$B$7:$B$167,'Force mapping'!$E$7:$E$167)) -> 536 | P5: =IF((K5*1) = 1, ((O5/1000000)/$A$7)*1000, $C$7) -> 0.62325581 | Q5: =(N5/($A$4/$A$7))*100 -> 5.0541045 | R5: =IF(ABS(U5)>80, 0, LOOKUP(V5,'Force mapping'!$B$7:$B$167,'Force mapping'!$D$7:$D$167) * (N5/5) * SIGN(U5)) -> 0 | S5: =(R5/($A$10/1000)) -> 0 | T5: =T4+(S4/1000)*$A$16 -> 27.98 | U5: =U4-((T4*$A$16) + (0.5 * (T5-T4))) -> 79.601 | V5: =(ROUND(ABS(U5)*2,0))/2 -> 79.5 | W5: =W4 - B10 -> 4.4198838 | X5: =(0.5 * (A10 / 1000) * T204^2) - (0.5 * (A10 / 1000) * B10^2) -> 2.2950998 | Y5: =Y4/D4 -> 0.60165592
A6: Resistance: | B6: Inductance: | C6: Time Constant: | E6: =E5+1 -> 2 | F6: =E6*$A$16 -> 0.1 | G6: =F6+P6 -> 0.72325581 | H6: =I6/($B$4/1000000) -> 389.75033 | I6: =IF((K5*1)=1,I5-((N5/1000)*$A$16),I5) -> 1.788954 | J6: =(((I6*H6)/2)/$D$4)*100 -> 99.872005 | K6: =AND(F6>($A$13-$A$16),F6<($B$13+$A$16)) -> TRUE | L6: =(H5/$A$7)*K6 -> 453.48837 | M6: =M5+(L6-M5)*0.63 -> 430.51783 | N6: =N5+((M5-N5)/((G5-F5)/$A$16)) -> 52.481156 | O6: =IF(ABS(U6)>80,$B$7, LOOKUP(V6,'Force mapping'!$B$7:$B$167,'Force mapping'!$E$7:$E$167)) -> 536 | P6: =IF((K6*1) = 1, ((O6/1000000)/$A$7)*1000, $C$7) -> 0.62325581 | Q6: =(N6/($A$4/$A$7))*100 -> 11.572768 | R6: =IF(ABS(U6)>80, 0, LOOKUP(V6,'Force mapping'!$B$7:$B$167,'Force mapping'!$D$7:$D$167) * (N6/5) * SIGN(U6)) -> 0 | S6: =(R6/($A$10/1000)) -> 0 | T6: =T5+(S5/1000)*$A$16 -> 27.98 | U6: =U5-((T5*$A$16) + (0.5 * (T6-T5))) -> 78.202 | V6: =(ROUND(ABS(U6)*2,0))/2 -> 78
A7: 0.86 | B7: 536 | C7: 0.623 | E7: =E6+1 -> 3 | F7: =E7*$A$16 -> 0.15 | G7: =F7+P7 -> 0.77325581 | H7: =I7/($B$4/1000000) -> 389.17864 | I7: =IF((K6*1)=1,I6-((N6/1000)*$A$16),I6) -> 1.78633 | J7: =(((I7*H7)/2)/$D$4)*100 -> 99.579233 | K7: =AND(F7>($A$13-$A$16),F7<($B$13+$A$16)) -> TRUE | L7: =(H6/$A$7)*K7 -> 453.19806 | M7: =M6+(L7-M6)*0.63 -> 444.80637 | N7: =N6+((M6-N6)/((G6-F6)/$A$16)) -> 82.808725 | O7: =IF(ABS(U7)>80,$B$7, LOOKUP(V7,'Force mapping'!$B$7:$B$167,'Force mapping'!$E$7:$E$167)) -> 536 | P7: =IF((K7*1) = 1, ((O7/1000000)/$A$7)*1000, $C$7) -> 0.62325581 | Q7: =(N7/($A$4/$A$7))*100 -> 18.260385 | R7: =IF(ABS(U7)>80, 0, LOOKUP(V7,'Force mapping'!$B$7:$B$167,'Force mapping'!$D$7:$D$167) * (N7/5) * SIGN(U7)) -> 0 | S7: =(R7/($A$10/1000)) -> 0 | T7: =T6+(S6/1000)*$A$16 -> 27.98 | U7: =U6-((T6*$A$16) + (0.5 * (T7-T6))) -> 76.803 | V7: =(ROUND(ABS(U7)*2,0))/2 -> 77
A8: PROJECTILE PROPERTIES | E8: =E7+1 -> 4 | F8: =E8*$A$16 -> 0.2 | G8: =F8+P8 -> 0.82325581 | H8: =I8/($B$4/1000000) -> 388.27658 | I8: =IF((K7*1)=1,I7-((N7/1000)*$A$16),I7) -> 1.7821895 | J8: =(((I8*H8)/2)/$D$4)*100 -> 99.118149 | K8: =AND(F8>($A$13-$A$16),F8<($B$13+$A$16)) -> TRUE | L8: =(H7/$A$7)*K8 -> 452.5333 | M8: =M7+(L8-M7)*0.63 -> 449.67434 | N8: =N7+((M7-N7)/((G7-F7)/$A$16)) -> 111.84958 | O8: =IF(ABS(U8)>80,$B$7, LOOKUP(V8,'Force mapping'!$B$7:$B$167,'Force mapping'!$E$7:$E$167)) -> 536 | P8: =IF((K8*1) = 1, ((O8/1000000)/$A$7)*1000, $C$7) -> 0.62325581 | Q8: =(N8/($A$4/$A$7))*100 -> 24.664267 | R8: =IF(ABS(U8)>80, 0, LOOKUP(V8,'Force mapping'!$B$7:$B$167,'Force mapping'!$D$7:$D$167) * (N8/5) * SIGN(U8)) -> 0 | S8: =(R8/($A$10/1000)) -> 0 | T8: =T7+(S7/1000)*$A$16 -> 27.98 | U8: =U7-((T7*$A$16) + (0.5 * (T8-T7))) -> 75.404 | V8: =(ROUND(ABS(U8)*2,0))/2 -> 75.5
A9: Mass: | B9: Starting Speed: | C9: Starting Position: | E9: =E8+1 -> 5 | F9: =E9*$A$16 -> 0.25 | G9: =F9+P9 -> 0.87325581 | H9: =I9/($B$4/1000000) -> 387.05818 | I9: =IF((K8*1)=1,I8-((N8/1000)*$A$16),I8) -> 1.776597 | J9: =(((I9*H9)/2)/$D$4)*100 -> 98.497063 | K9: =AND(F9>($A$13-$A$16),F9<($B$13+$A$16)) -> TRUE | L9: =(H8/$A$7)*K9 -> 451.4844 | M9: =M8+(L9-M8)*0.63 -> 450.81468 | N9: =N8+((M8-N8)/((G8-F8)/$A$16)) -> 138.95119 | O9: =IF(ABS(U9)>80,$B$7, LOOKUP(V9,'Force mapping'!$B$7:$B$167,'Force mapping'!$E$7:$E$167)) -> 536 | P9: =IF((K9*1) = 1, ((O9/1000000)/$A$7)*1000, $C$7) -> 0.62325581 | Q9: =(N9/($A$4/$A$7))*100 -> 30.64052 | R9: =IF(ABS(U9)>80, 0, LOOKUP(V9,'Force mapping'!$B$7:$B$167,'Force mapping'!$D$7:$D$167) * (N9/5) * SIGN(U9)) -> 0 | S9: =(R9/($A$10/1000)) -> 0 | T9: =T8+(S8/1000)*$A$16 -> 27.98 | U9: =U8-((T8*$A$16) + (0.5 * (T9-T8))) -> 74.005 | V9: =(ROUND(ABS(U9)*2,0))/2 -> 74
A10: 17.2 | B10: 27.98 | C10: 81 | E10: =E9+1 -> 6 | F10: =E10*$A$16 -> 0.3 | G10: =F10+P10 -> 0.92325581 | H10: =I10/($B$4/1000000) -> 385.54455 | I10: =IF((K9*1)=1,I9-((N9/1000)*$A$16),I9) -> 1.7696495 | J10: =(((I10*H10)/2)/$D$4)*100 -> 97.728204 | K10: =AND(F10>($A$13-$A$16),F10<($B$13+$A$16)) -> TRUE | L10: =(H9/$A$7)*K10 -> 450.06765 | M10: =M9+(L10-M9)*0.63 -> 450.34405 | N10: =N9+((M9-N9)/((G9-F9)/$A$16)) -> 163.97009 | O10: =IF(ABS(U10)>80,$B$7, LOOKUP(V10,'Force mapping'!$B$7:$B$167,'Force mapping'!$E$7:$E$167)) -> 536 | P10: =IF((K10*1) = 1, ((O10/1000000)/$A$7)*1000, $C$7) -> 0.62325581 | Q10: =(N10/($A$4/$A$7))*100 -> 36.157508 | R10: =IF(ABS(U10)>80, 0, LOOKUP(V10,'Force mapping'!$B$7:$B$167,'Force mapping'!$D$7:$D$167) * (N10/5) * SIGN(U10)) -> 0 | S10: =(R10/($A$10/1000)) -> 0 | T10: =T9+(S9/1000)*$A$16 -> 27.98 | U10: =U9-((T9*$A$16) + (0.5 * (T10-T9))) -> 72.606 | V10: =(ROUND(ABS(U10)*2,0))/2 -> 72.5
A11: SEMICONDUCTOR PROPERTIES | E11: =E10+1 -> 7 | F11: =E11*$A$16 -> 0.35 | G11: =F11+P11 -> 0.97325581 | H11: =I11/($B$4/1000000) -> 383.75838 | I11: =IF((K10*1)=1,I10-((N10/1000)*$A$16),I10) -> 1.761451 | J11: =(((I11*H11)/2)/$D$4)*100 -> 96.824784 | K11: =AND(F11>($A$13-$A$16),F11<($B$13+$A$16)) -> TRUE | L11: =(H10/$A$7)*K11 -> 448.30761 | M11: =M10+(L11-M10)*0.63 -> 449.0611 | N11: =N10+((M10-N10)/((G10-F10)/$A$16)) -> 186.94412 | O11: =IF(ABS(U11)>80,$B$7, LOOKUP(V11,'Force mapping'!$B$7:$B$167,'Force mapping'!$E$7:$E$167)) -> 536 | P11: =IF((K11*1) = 1, ((O11/1000000)/$A$7)*1000, $C$7) -> 0.62325581 | Q11: =(N11/($A$4/$A$7))*100 -> 41.223576 | R11: =IF(ABS(U11)>80, 0, LOOKUP(V11,'Force mapping'!$B$7:$B$167,'Force mapping'!$D$7:$D$167) * (N11/5) * SIGN(U11)) -> 0 | S11: =(R11/($A$10/1000)) -> 0 | T11: =T10+(S10/1000)*$A$16 -> 27.98 | U11: =U10-((T10*$A$16) + (0.5 * (T11-T10))) -> 71.207 | V11: =(ROUND(ABS(U11)*2,0))/2 -> 71
A12: On Time: | B12: Off Time: | C12: Max Current: | E12: =E11+1 -> 8 | F12: =E12*$A$16 -> 0.4 | G12: =F12+P12 -> 1.0232558 | H12: =I12/($B$4/1000000) -> 381.72195 | I12: =IF((K11*1)=1,I11-((N11/1000)*$A$16),I11) -> 1.7521038 | J12: =(((I12*H12)/2)/$D$4)*100 -> 95.799901 | K12: =AND(F12>($A$13-$A$16),F12<($B$13+$A$16)) -> TRUE | L12: =(H11/$A$7)*K12 -> 446.23068 | M12: =M11+(L12-M11)*0.63 -> 447.27793 | N12: =N11+((M11-N11)/((G11-F11)/$A$16)) -> 207.97216 | O12: =IF(ABS(U12)>80,$B$7, LOOKUP(V12,'Force mapping'!$B$7:$B$167,'Force mapping'!$E$7:$E$167)) -> 536 | P12: =IF((K12*1) = 1, ((O12/1000000)/$A$7)*1000, $C$7) -> 0.62325581 | Q12: =(N12/($A$4/$A$7))*100 -> 45.860528 | R12: =IF(ABS(U12)>80, 0, LOOKUP(V12,'Force mapping'!$B$7:$B$167,'Force mapping'!$D$7:$D$167) * (N12/5) * SIGN(U12)) -> 0 | S12: =(R12/($A$10/1000)) -> 0 | T12: =T11+(S11/1000)*$A$16 -> 27.98 | U12: =U11-((T11*$A$16) + (0.5 * (T12-T11))) -> 69.808 | V12: =(ROUND(ABS(U12)*2,0))/2 -> 70
A13: 0 | B13: 2.2 | E13: =E12+1 -> 9 | F13: =E13*$A$16 -> 0.45 | G13: =F13+P13 -> 1.0732558 | H13: =I13/($B$4/1000000) -> 379.45646 | I13: =IF((K12*1)=1,I12-((N12/1000)*$A$16),I12) -> 1.7417052 | J13: =(((I13*H13)/2)/$D$4)*100 -> 94.666145 | K13: =AND(F13>($A$13-$A$16),F13<($B$13+$A$16)) -> TRUE | L13: =(H12/$A$7)*K13 -> 443.86274 | M13: =M12+(L13-M12)*0.63 -> 445.12636 | N13: =N12+((M12-N12)/((G12-F12)/$A$16)) -> 227.1702 | O13: =IF(ABS(U13)>80,$B$7, LOOKUP(V13,'Force mapping'!$B$7:$B$167,'Force mapping'!$E$7:$E$167)) -> 536 | P13: =IF((K13*1) = 1, ((O13/1000000)/$A$7)*1000, $C$7) -> 0.62325581 | Q13: =(N13/($A$4/$A$7))*100 -> 50.093942 | R13: =IF(ABS(U13)>80, 0, LOOKUP(V13,'Force mapping'!$B$7:$B$167,'Force mapping'!$D$7:$D$167) * (N13/5) * SIGN(U13)) -> 0 | S13: =(R13/($A$10/1000)) -> 0 | T13: =T12+(S12/1000)*$A$16 -> 27.98 | U13: =U12-((T12*$A$16) + (0.5 * (T13-T12))) -> 68.409 | V13: =(ROUND(ABS(U13)*2,0))/2 -> 68.5
A14: SIMULATION PROPERTIES | E14: =E13+1 -> 10 | F14: =E14*$A$16 -> 0.5 | G14: =F14+P14 -> 1.1232558 | H14: =I14/($B$4/1000000) -> 376.98184 | I14: =IF((K13*1)=1,I13-((N13/1000)*$A$16),I13) -> 1.7303466 | J14: =(((I14*H14)/2)/$D$4)*100 -> 93.435443 | K14: =AND(F14>($A$13-$A$16),F14<($B$13+$A$16)) -> TRUE | L14: =(H13/$A$7)*K14 -> 441.22844 | M14: =M13+(L14-M13)*0.63 -> 442.67067 | N14: =N13+((M13-N13)/((G13-F13)/$A$16)) -> 244.65549 | O14: =IF(ABS(U14)>80,$B$7, LOOKUP(V14,'Force mapping'!$B$7:$B$167,'Force mapping'!$E$7:$E$167)) -> 536 | P14: =IF((K14*1) = 1, ((O14/1000000)/$A$7)*1000, $C$7) -> 0.62325581 | Q14: =(N14/($A$4/$A$7))*100 -> 53.949672 | R14: =IF(ABS(U14)>80, 0, LOOKUP(V14,'Force mapping'!$B$7:$B$167,'Force mapping'!$D$7:$D$167) * (N14/5) * SIGN(U14)) -> 0 | S14: =(R14/($A$10/1000)) -> 0 | T14: =T13+(S13/1000)*$A$16 -> 27.98 | U14: =U13-((T13*$A$16) + (0.5 * (T14-T13))) -> 67.01 | V14: =(ROUND(ABS(U14)*2,0))/2 -> 67
A15: Time Increment: | E15: =E14+1 -> 11 | F15: =E15*$A$16 -> 0.55 | G15: =F15+P15 -> 1.1732558 | H15: =I15/($B$4/1000000) -> 374.31675 | I15: =IF((K14*1)=1,I14-((N14/1000)*$A$16),I14) -> 1.7181139 | J15: =(((I15*H15)/2)/$D$4)*100 -> 92.119019 | K15: =AND(F15>($A$13-$A$16),F15<($B$13+$A$16)) -> TRUE | L15: =(H14/$A$7)*K15 -> 438.35098 | M15: =M14+(L15-M14)*0.63 -> 439.94926 | N15: =N14+((M14-N14)/((G14-F14)/$A$16)) -> 260.54104 | O15: =IF(ABS(U15)>80,$B$7, LOOKUP(V15,'Force mapping'!$B$7:$B$167,'Force mapping'!$E$7:$E$167)) -> 536 | P15: =IF((K15*1) = 1, ((O15/1000000)/$A$7)*1000, $C$7) -> 0.62325581 | Q15: =(N15/($A$4/$A$7))*100 -> 57.452639 | R15: =IF(ABS(U15)>80, 0, LOOKUP(V15,'Force mapping'!$B$7:$B$167,'Force mapping'!$D$7:$D$167) * (N15/5) * SIGN(U15)) -> 0 | S15: =(R15/($A$10/1000)) -> 0 | T15: =T14+(S14/1000)*$A$16 -> 27.98 | U15: =U14-((T14*$A$16) + (0.5 * (T15-T14))) -> 65.611 | V15: =(ROUND(ABS(U15)*2,0))/2 -> 65.5
A16: 0.05 | E16: =E15+1 -> 12 | F16: =E16*$A$16 -> 0.6 | G16: =F16+P16 -> 1.2232558 | H16: =I16/($B$4/1000000) -> 371.47861 | I16: =IF((K15*1)=1,I15-((N15/1000)*$A$16),I15) -> 1.7050868 | J16: =(((I16*H16)/2)/$D$4)*100 -> 90.727389 | K16: =AND(F16>($A$13-$A$16),F16<($B$13+$A$16)) -> TRUE | L16: =(H15/$A$7)*K16 -> 435.25203 | M16: =M15+(L16-M15)*0.63 -> 436.99001 | N16: =N15+((M15-N15)/((G15-F15)/$A$16)) -> 274.93386 | O16: =IF(ABS(U16)>80,$B$7, LOOKUP(V16,'Force mapping'!$B$7:$B$167,'Force mapping'!$E$7:$E$167)) -> 536 | P16: =IF((K16*1) = 1, ((O16/1000000)/$A$7)*1000, $C$7) -> 0.62325581 | Q16: =(N16/($A$4/$A$7))*100 -> 60.626441 | R16: =IF(ABS(U16)>80, 0, LOOKUP(V16,'Force mapping'!$B$7:$B$167,'Force mapping'!$D$7:$D$167) * (N16/5) * SIGN(U16)) -> 0 | S16: =(R16/($A$10/1000)) -> 0 | T16: =T15+(S15/1000)*$A$16 -> 27.98 | U16: =U15-((T15*$A$16) + (0.5 * (T16-T15))) -> 64.212 | V16: =(ROUND(ABS(U16)*2,0))/2 -> 64
E17: =E16+1 -> 13 | F17: =E17*$A$16 -> 0.65 | G17: =F17+P17 -> 1.2732558 | H17: =I17/($B$4/1000000) -> 368.48369 | I17: =IF((K16*1)=1,I16-((N16/1000)*$A$16),I16) -> 1.6913401 | J17: =(((I17*H17)/2)/$D$4)*100 -> 89.270367 | K17: =AND(F17>($A$13-$A$16),F17<($B$13+$A$16)) -> TRUE | L17: =(H16/$A$7)*K17 -> 431.95187 | M17: =M16+(L17-M16)*0.63 -> 433.81598 | N17: =N16+((M16-N16)/((G16-F16)/$A$16)) -> 287.93463 | O17: =IF(ABS(U17)>80,$B$7, LOOKUP(V17,'Force mapping'!$B$7:$B$167,'Force mapping'!$E$7:$E$167)) -> 536 | P17: =IF((K17*1) = 1, ((O17/1000000)/$A$7)*1000, $C$7) -> 0.62325581 | Q17: =(N17/($A$4/$A$7))*100 -> 63.493278 | R17: =IF(ABS(U17)>80, 0, LOOKUP(V17,'Force mapping'!$B$7:$B$167,'Force mapping'!$D$7:$D$167) * (N17/5) * SIGN(U17)) -> 0 | S17: =(R17/($A$10/1000)) -> 0 | T17: =T16+(S16/1000)*$A$16 -> 27.98 | U17: =U16-((T16*$A$16) + (0.5 * (T17-T16))) -> 62.813 | V17: =(ROUND(ABS(U17)*2,0))/2 -> 63
